<?xml version="1.0" encoding="utf-8"?>
<!-- This URDF was automatically created by SolidWorks to URDF Exporter! Originally created by Stephen Brawner (brawner@gmail.com) 
     Commit Version: 1.6.0-1-g15f4949  Build Version: 1.6.7594.29634
     For more information, please see http://wiki.ros.org/sw_urdf_exporter -->
<robot
  name="sii_arm">
  <link
    name="base_link">
    <inertial>
      <origin
        xyz="-4.4161E-05 5.3119E-09 0.017678"
        rpy="0 0 0" />
      <mass
        value="0.362" />
      <inertia
        ixx="9.6033E-05"
        ixy="1.8597E-08"
        ixz="-1.3884E-08"
        iyy="0.00041488"
        iyz="5.2358E-12"
        izz="0.00047014" />
    </inertial>
    <visual>
      <origin
        xyz="0 0 0"
        rpy="0 0 0" />
      <geometry>
        <mesh
          filename="/home/ubuntu/codes/sii_arm/assets/sii_arm/meshes/base_link.STL" />
      </geometry>
      <material
        name="">
        <color
          rgba="0.75294 0.75294 0.75294 1" />
      </material>
    </visual>
    <collision>
      <origin
        xyz="0 0 0"
        rpy="0 0 0" />
      <geometry>
        <mesh
          filename="/home/ubuntu/codes/sii_arm/assets/sii_arm/meshes/base_link.STL" />
      </geometry>
    </collision>
  </link>
  <link
    name="link1">
    <inertial>
      <origin
        xyz="0.00707859698669122 -0.00434330957019007 0.026713005518239"
        rpy="0 0 0" />
      <mass
        value="0.0770" />
      <inertia
        ixx="1.25374082996922E-05"
        ixy="2.35360826477428E-20"
        ixz="-2.85347898906561E-06"
        iyy="1.28839283702013E-05"
        iyz="1.22941709166716E-20"
        izz="1.07726251285965E-05" />
    </inertial>
    <visual>
      <origin
        xyz="0 0 0"
        rpy="0 0 0" />
      <geometry>
        <mesh
          filename="/home/ubuntu/codes/sii_arm/assets/sii_arm/meshes/link1.STL" />
      </geometry>
      <material
        name="">
        <color
          rgba="1 1 1 1" />
      </material>
    </visual>
    <collision>
      <origin
        xyz="0 0 0"
        rpy="0 0 0" />
      <geometry>
        <mesh
          filename="/home/ubuntu/codes/sii_arm/assets/sii_arm/meshes/link1.STL" />
      </geometry>
    </collision>
  </link>
  <joint
    name="joint1"
    type="revolute">
    <origin
      xyz="0 0 0.0633"
      rpy="0 0 0" />
    <parent
      link="base_link" />
    <child
      link="link1" />
    <axis
      xyz="0 0 1" />
    <limit
      lower="-6.28"
      upper="6.28"
      effort="0"
      velocity="0" />
  </joint>
  <link
    name="link2">
    <inertial>
      <origin
        xyz="-0.131999999999995 4.71844785465692E-15 0.0283597358633429"
        rpy="0 0 0" />
      <mass
        value="1.3153" />
      <inertia
        ixx="0.000132893749398952"
        ixy="3.71930780587879E-08"
        ixz="3.69519340442436E-18"
        iyy="0.000434598829500377"
        iyz="1.34090171590558E-19"
        izz="0.000463250516319811" />
    </inertial>
    <visual>
      <origin
        xyz="0 0 0"
        rpy="0 0 0" />
      <geometry>
        <mesh
          filename="/home/ubuntu/codes/sii_arm/assets/sii_arm/meshes/link2.STL" />
      </geometry>
      <material
        name="">
        <color
          rgba="0.752941176470588 0.752941176470588 0.752941176470588 1" />
      </material>
    </visual>
    <collision>
      <origin
        xyz="0 0 0"
        rpy="0 0 0" />
      <geometry>
        <mesh
          filename="/home/ubuntu/codes/sii_arm/assets/sii_arm/meshes/link2.STL" />
      </geometry>
    </collision>
  </link>
  <joint
    name="joint2"
    type="revolute">
    <origin
      xyz="0.019 -0.0275 0.052409"
      rpy="-1.5708 0 0" />
    <parent
      link="link1" />
    <child
      link="link2" />
    <axis
      xyz="0 0 1" />
    <limit
      lower="-6.28"
      upper="6.28"
      effort="0"
      velocity="0" />
  </joint>
  <link
    name="link3">
    <inertial>
      <origin
        xyz="0.0691164120694006 -0.0517481368067969 0.0320239443295308"
        rpy="0 0 0" />
      <mass
        value="0.5352" />
      <inertia
        ixx="8.2977561092953E-05"
        ixy="5.67306781151032E-06"
        ixz="-6.81858709315202E-10"
        iyy="0.000335535721506396"
        iyz="2.24716495714001E-09"
        izz="0.000368685770241735" />
    </inertial>
    <visual>
      <origin
        xyz="0 0 0"
        rpy="0 0 0" />
      <geometry>
        <mesh
          filename="/home/ubuntu/codes/sii_arm/assets/sii_arm/meshes/link3.STL" />
      </geometry>
      <material
        name="">
        <color
          rgba="1 1 1 1" />
      </material>
    </visual>
    <collision>
      <origin
        xyz="0 0 0"
        rpy="0 0 0" />
      <geometry>
        <mesh
          filename="/home/ubuntu/codes/sii_arm/assets/sii_arm/meshes/link3.STL" />
      </geometry>
    </collision>
  </link>
  <joint
    name="joint3"
    type="revolute">
    <origin
      xyz="-0.264 0 -0.0053"
      rpy="0 0 0" />
    <parent
      link="link2" />
    <child
      link="link3" />
    <axis
      xyz="0 0 -1" />
    <limit
      lower="-6.28"
      upper="6.28"
      effort="0"
      velocity="0" />
  </joint>
  <link
    name="link4">
    <inertial>
      <origin
        xyz="-0.0359499146548394 -0.0298356046367815 -0.0244014167334243"
        rpy="0 0 0" />
      <mass
        value="0.7211" />
      <inertia
        ixx="7.94008088377001E-05"
        ixy="-2.68989534968233E-08"
        ixz="2.69000796443167E-08"
        iyy="9.26226237856924E-05"
        iyz="1.36979059366666E-07"
        izz="8.80199287308234E-05" />
    </inertial>
    <visual>
      <origin
        xyz="0 0 0"
        rpy="0 0 0" />
      <geometry>
        <mesh
          filename="/home/ubuntu/codes/sii_arm/assets/sii_arm/meshes/link4.STL" />
      </geometry>
      <material
        name="">
        <color
          rgba="0.752941176470588 0.752941176470588 0.752941176470588 1" />
      </material>
    </visual>
    <collision>
      <origin
        xyz="0 0 0"
        rpy="0 0 0" />
      <geometry>
        <mesh
          filename="/home/ubuntu/codes/sii_arm/assets/sii_arm/meshes/link4.STL" />
      </geometry>
    </collision>
  </link>
  <joint
    name="joint4"
    type="revolute">
    <origin
      xyz="0.2235 -0.06025 0.0075"
      rpy="-3.1416 0 3.1416" />
    <parent
      link="link3" />
    <child
      link="link4" />
    <axis
      xyz="0 0 1" />
    <limit
      lower="-6.28"
      upper="6.28"
      effort="0"
      velocity="0" />
  </joint>
  <link
    name="link5">
    <inertial>
      <origin
        xyz="0.0143899676824716 -1.28077697342972E-05 0.0055270468665741"
        rpy="0 0 0" />
      <mass
        value="0.3497" />
      <inertia
        ixx="5.17590155942997E-05"
        ixy="6.84895460214422E-08"
        ixz="2.94401664070318E-10"
        iyy="3.71782837739973E-05"
        iyz="2.71943600596407E-08"
        izz="3.74998373769998E-05" />
    </inertial>
    <visual>
      <origin
        xyz="0 0 0"
        rpy="0 0 0" />
      <geometry>
        <mesh
          filename="/home/ubuntu/codes/sii_arm/assets/sii_arm/meshes/link5.STL" />
      </geometry>
      <material
        name="">
        <color
          rgba="1 1 1 1" />
      </material>
    </visual>
    <collision>
      <origin
        xyz="0 0 0"
        rpy="0 0 0" />
      <geometry>
        <mesh
          filename="/home/ubuntu/codes/sii_arm/assets/sii_arm/meshes/link5.STL" />
      </geometry>
    </collision>
  </link>
  <joint
    name="joint5"
    type="revolute">
    <origin
      xyz="-0.075 0.0015 -0.027"
      rpy="-1.5708 0 3.1416" />
    <parent
      link="link4" />
    <child
      link="link5" />
    <axis
      xyz="0 0 -1" />
    <limit
      lower="-6.28"
      upper="6.28"
      effort="0"
      velocity="0" />
  </joint>
  <link
    name="link6">
    <inertial>
      <origin
        xyz="0.0144947562777893 3.48836556239608E-05 0.099654862075938"
        rpy="0 0 0" />
      <mass
        value="0.620" />
      <inertia
        ixx="0.000169829787171198"
        ixy="-9.54442662622359E-08"
        ixz="-3.24153942640785E-06"
        iyy="0.0002013671229172"
        iyz="-6.84844476948465E-08"
        izz="0.000256378611780147" />
    </inertial>
    <visual>
      <origin
        xyz="0 0 0"
        rpy="0 0 0" />
      <geometry>
        <mesh
          filename="/home/ubuntu/codes/sii_arm/assets/sii_arm/meshes/link6.STL" />
      </geometry>
      <material
        name="">
        <color
          rgba="0.752941176470588 0.752941176470588 0.752941176470588 1" />
      </material>
    </visual>
    <collision>
      <origin
        xyz="0 0 0"
        rpy="0 0 0" />
      <geometry>
        <mesh
          filename="/home/ubuntu/codes/sii_arm/assets/sii_arm/meshes/link6.STL" />
      </geometry>
    </collision>
  </link>
  <joint
    name="joint6"
    type="revolute">
    <origin
      xyz="0 0 0"
      rpy="0 1.5708 0" />
    <parent
      link="link5" />
    <child
      link="link6" />
    <axis
      xyz="0 0 1" />
    <limit
      lower="-6.28"
      upper="6.28"
      effort="0"
      velocity="0" />
  </joint>
</robot>