<?xml version="1.0" encoding="utf-8"?>
<!-- This URDF was automatically created by SolidWorks to URDF Exporter! Originally created by Stephen Brawner (brawner@gmail.com) 
     Commit Version: 1.6.0-1-g15f4949  Build Version: 1.6.7594.29634
     For more information, please see http://wiki.ros.org/sw_urdf_exporter -->
<robot
  name="STEP">
  <link
    name="base_link">
    <inertial>
      <origin
        xyz="-2.286E-05 2.7497E-09 0.01623"
        rpy="0 0 0" />
      <mass
        value="0.50446" />
      <inertia
        ixx="0.00018822"
        ixy="1.8597E-08"
        ixz="-1.3884E-08"
        iyy="0.0010487"
        iyz="5.2358E-12"
        izz="0.0011932" />
    </inertial>
    <visual>
      <origin
        xyz="0 0 0"
        rpy="0 0 0" />
      <geometry>
        <mesh
          filename="package://openeai_arm_urdf_ros2/meshes/base_link.STL" />
      </geometry>
      <material
        name="openeai">
        <color
          rgba="0.89804 0.91765 0.92941 1" />
      </material>
    </visual>
    <collision>
      <origin
        xyz="0 0 0"
        rpy="0 0 0" />
      <geometry>
        <mesh
          filename="package://openeai_arm_urdf_ros2/meshes/base_link.STL" />
      </geometry>
    </collision>
  </link>
  <link
    name="link1">
    <inertial>
      <origin
        xyz="-0.0045469 -0.0028108 -0.030271"
        rpy="0 0 0" />
      <mass
        value="0.419464" />
      <inertia
        ixx="2.8404E-05"
        ixy="1.2197E-08"
        ixz="6.0756E-06"
        iyy="2.686E-05"
        iyz="-2.1814E-08"
        izz="2.493E-05" />
    </inertial>
    <visual>
      <origin
        xyz="0 0 0"
        rpy="0 0 0" />
      <geometry>
        <mesh
          filename="package://openeai_arm_urdf_ros2/meshes/link1.STL" />
      </geometry>
      <material
        name="openeai1">
        <color
          rgba="0.89804 0.91765 0.92941 1" />
      </material>
    </visual>
    <collision>
      <origin
        xyz="0 0 0"
        rpy="0 0 0" />
      <geometry>
        <mesh
          filename="package://openeai_arm_urdf_ros2/meshes/link1.STL" />
      </geometry>
    </collision>
  </link>
  <joint
    name="1"
    type="revolute">
    <origin
      xyz="0 0 0.12371"
      rpy="0 0 0" />
    <parent
      link="base_link" />
    <child
      link="link1" />
    <axis
      xyz="0 0 1" />
    <limit
      lower="-1.57"
      upper="1.57"
      effort="0"
      velocity="0" />
  </joint>
  <link
    name="link2">
    <inertial>
      <origin
        xyz="0.13073 1.5099E-12 0.0027189"
        rpy="0 0 0" />
      <mass
        value="1.5389" />
      <inertia
        ixx="0.00021808"
        ixy="3.8197E-08"
        ixz="-6.9356E-19"
        iyy="0.0010335"
        iyz="-8.1073E-16"
        izz="0.0011036" />
    </inertial>
    <visual>
      <origin
        xyz="0 0 0"
        rpy="0 0 0" />
      <geometry>
        <mesh
          filename="package://openeai_arm_urdf_ros2/meshes/link2.STL" />
      </geometry>
      <material
        name="openeai2">
        <color
          rgba="0.7451 0.7451 0.7451 1" />
      </material>
    </visual>
    <collision>
      <origin
        xyz="0 0 0"
        rpy="0 0 0" />
      <geometry>
        <mesh
          filename="package://openeai_arm_urdf_ros2/meshes/link2.STL" />
      </geometry>
    </collision>
  </link>
  <joint
    name="2"
    type="revolute">
    <origin
      xyz="-0.019 0 0"
      rpy="1.5708 0 3.1416" />
    <parent
      link="link1" />
    <child
      link="link2" />
    <axis
      xyz="0 0 1" />
    <limit
      lower="-0.2"
      upper="3.662"
      effort="0"
      velocity="0" />
  </joint>
  <link
    name="link3">
    <inertial>
      <origin
        xyz="0.1657 0.017535 -0.0016971"
        rpy="0 0 0" />
      <mass
        value="1.01598" />
      <inertia
        ixx="0.00028128"
        ixy="0.00016388"
        ixz="-1.4389E-06"
        iyy="0.00089643"
        iyz="3.8117E-07"
        izz="0.0010603" />
    </inertial>
    <visual>
      <origin
        xyz="0 0 0"
        rpy="0 0 0" />
      <geometry>
        <mesh
          filename="package://openeai_arm_urdf_ros2/meshes/link3.STL" />
      </geometry>
      <material
        name="openeai3">
        <color
          rgba="0.7451 0.7451 0.7451 1" />
      </material>
    </visual>
    <collision>
      <origin
        xyz="0 0 0"
        rpy="0 0 0" />
      <geometry>
        <mesh
          filename="package://openeai_arm_urdf_ros2/meshes/link3.STL" />
      </geometry>
    </collision>
  </link>
  <joint
    name="3"
    type="revolute">
    <origin
      xyz="0.264 0 0"
      rpy="3.1416 0 2.8783" />
    <parent
      link="link2" />
    <child
      link="link3" />
    <axis
      xyz="0 0 1" />
    <limit
      lower="-0.1"
      upper="3.1416"
      effort="0"
      velocity="0" />
  </joint>
  <link
    name="link4">
    <inertial>
      <origin
        xyz="0.052533 0.038815 -0.041806"
        rpy="0 0 0" />
      <mass
        value="0.53515" />
      <inertia
        ixx="7.9691E-05"
        ixy="2.9447E-10"
        ixz="-4.225E-08"
        iyy="9.4211E-05"
        iyz="-6.849E-08"
        izz="6.8988E-05" />
    </inertial>
    <visual>
      <origin
        xyz="0 0 0"
        rpy="0 0 0" />
      <geometry>
        <mesh
          filename="package://openeai_arm_urdf_ros2/meshes/link4.STL" />
      </geometry>
      <material
        name="openeai4">
        <color
          rgba="0.89804 0.91765 0.92941 1" />
      </material>
    </visual>
    <collision>
      <origin
        xyz="0 0 0"
        rpy="0 0 0" />
      <geometry>
        <mesh
          filename="package://openeai_arm_urdf_ros2/meshes/link4.STL" />
      </geometry>
    </collision>
  </link>
  <joint
    name="4"
    type="revolute">
    <origin
      xyz="0.23148 0 0"
      rpy="0 0 -0.26332" />
    <parent
      link="link3" />
    <child
      link="link4" />
    <axis
      xyz="0 0 1" />
    <limit
      lower="-1.5708"
      upper="1.5708"
      effort="0"
      velocity="0" />
  </joint>
  <link
    name="link5">
    <inertial>
      <origin
        xyz="1.0201E-05 -0.016598 -0.0033441"
        rpy="0 0 0" />
      <mass
        value="0.46797" />
      <inertia
        ixx="4.8034E-05"
        ixy="6.849E-08"
        ixz="2.7193E-08"
        iyy="6.7289E-05"
        iyz="2.9447E-10"
        izz="4.812E-05" />
    </inertial>
    <visual>
      <origin
        xyz="0 0 0"
        rpy="0 0 0" />
      <geometry>
        <mesh
          filename="package://openeai_arm_urdf_ros2/meshes/link5.STL" />
      </geometry>
      <material
        name="openeai5">
        <color
          rgba="1 1 1 1" />
      </material>
    </visual>
    <collision>
      <origin
        xyz="0 0 0"
        rpy="0 0 0" />
      <geometry>
        <mesh
          filename="package://openeai_arm_urdf_ros2/meshes/link5.STL" />
      </geometry>
    </collision>
  </link>
  <joint
    name="5"
    type="revolute">
    <origin
      xyz="0.075 -0.0015 -0.0015"
      rpy="1.5708 -1.5708 0" />
    <parent
      link="link4" />
    <child
      link="link5" />
    <axis
      xyz="0 0 1" />
    <limit
      lower="-1.5708"
      upper="1.5708"
      effort="0"
      velocity="0" />
  </joint>
  <link
    name="link6">
    <inertial>
      <origin
        xyz="-3.4881E-05 0.014495 0.054359"
        rpy="0 0 0" />
      <mass
        value="0.63362" />
      <inertia
        ixx="0.00020137"
        ixy="9.5443E-08"
        ixz="6.8488E-08"
        iyy="0.00016983"
        iyz="-3.2415E-06"
        izz="0.00025638" />
    </inertial>
    <visual>
      <origin
        xyz="0 0 0"
        rpy="0 0 0" />
      <geometry>
        <mesh
          filename="package://openeai_arm_urdf_ros2/meshes/link6.STL" />
      </geometry>
      <material
        name="openeai6">
        <color
          rgba="1 1 1 1" />
      </material>
    </visual>
    <collision>
      <origin
        xyz="0 0 0"
        rpy="0 0 0" />
      <geometry>
        <mesh
          filename="package://openeai_arm_urdf_ros2/meshes/link6.STL" />
      </geometry>
    </collision>
  </link>
  <joint
    name="6"
    type="revolute">
    <origin
      xyz="0 -0.036 0"
      rpy="1.5708 0 0" />
    <parent
      link="link5" />
    <child
      link="link6" />
    <axis
      xyz="0 0 1" />
    <limit
      lower="-3.1416"
      upper="3.1416"
      effort="0"
      velocity="0" />
  </joint>
</robot>