<?xml version="1.0" encoding="utf-8"?>
<!-- This URDF was automatically created by SolidWorks to URDF Exporter! Originally created by Stephen Brawner (brawner@gmail.com) 
     Commit Version: 1.6.0-1-g15f4949  Build Version: 1.6.7594.29634
     For more information, please see http://wiki.ros.org/sw_urdf_exporter -->
<robot
  name="STEP">
  <link
    name="base_link">
    <inertial>
      <origin
        xyz="-0.26714 -0.017182 -0.031475"
        rpy="0 0 0" />
      <mass
        value="0.27193" />
      <inertia
        ixx="9.774E-05"
        ixy="1.3884E-08"
        ixz="1.8597E-08"
        iyy="0.00047337"
        iyz="-5.2358E-12"
        izz="0.00041659" />
    </inertial>
    <visual>
      <origin
        xyz="0 0 0"
        rpy="0 0 0" />
      <geometry>
        <mesh
          filename="package://STEP/meshes/base_link.STL" />
      </geometry>
      <material
        name="">
        <color
          rgba="0.75294 0.75294 0.75294 1" />
      </material>
    </visual>
    <collision>
      <origin
        xyz="0 0 0"
        rpy="0 0 0" />
      <geometry>
        <mesh
          filename="./STEP/meshes/base_link.STL" />
      </geometry>
    </collision>
  </link>
  <link
    name="link1">
    <inertial>
      <origin
        xyz="-0.0025304 -0.013278 0.0040932"
        rpy="0 0 0" />
      <mass
        value="0.036807" />
      <inertia
        ixx="1.0242E-05"
        ixy="8.0794E-09"
        ixz="-4.5173E-09"
        iyy="9.7905E-06"
        iyz="2.2502E-06"
        izz="1.0814E-05" />
    </inertial>
    <visual>
      <origin
        xyz="0 0 0"
        rpy="0 0 0" />
      <geometry>
        <mesh
          filename="./STEP/meshes/link1.STL" />
      </geometry>
      <material
        name="">
        <color
          rgba="1 1 1 1" />
      </material>
    </visual>
    <collision>
      <origin
        xyz="0 0 0"
        rpy="0 0 0" />
      <geometry>
        <mesh
          filename="package://STEP/meshes/link1.STL" />
      </geometry>
    </collision>
  </link>
  <joint
    name="1"
    type="revolute">
    <origin
      xyz="-0.2671 -0.0703 -0.031475"
      rpy="3.1416 -1.5708 0" />
    <parent
      link="base_link" />
    <child
      link="link1" />
    <axis
      xyz="0 1 0" />
    <limit
      lower="0"
      upper="6.2832"
      effort="0"
      velocity="0" />
  </joint>
  <link
    name="link2">
    <inertial>
      <origin
        xyz="0.13182 -0.028381 2.0955E-15"
        rpy="0 0 0" />
      <mass
        value="0.71932" />
      <inertia
        ixx="0.00017522"
        ixy="2.8279E-18"
        ixz="-3.7565E-08"
        iyy="0.00098649"
        iyz="3.5155E-19"
        izz="0.00095848" />
    </inertial>
    <visual>
      <origin
        xyz="0 0 0"
        rpy="0 0 0" />
      <geometry>
        <mesh
          filename="package://STEP/meshes/link2.STL" />
      </geometry>
      <material
        name="">
        <color
          rgba="0.7451 0.7451 0.7451 1" />
      </material>
    </visual>
    <collision>
      <origin
        xyz="0 0 0"
        rpy="0 0 0" />
      <geometry>
        <mesh
          filename="package://STEP/meshes/link2.STL" />
      </geometry>
    </collision>
  </link>
  <joint
    name="2"
    type="revolute">
    <origin
      xyz="0.02987 -0.045409 0.019"
      rpy="1.5708 -1.5708 0" />
    <parent
      link="link1" />
    <child
      link="link2" />
    <axis
      xyz="0 1 0" />
    <limit
      lower="0"
      upper="3.6652"
      effort="0"
      velocity="0" />
  </joint>
  <link
    name="link3">
    <inertial>
      <origin
        xyz="-0.035393 0.12109 -0.043695"
        rpy="0 0 0" />
      <mass
        value="0.59366" />
      <inertia
        ixx="0.00094997"
        ixy="1.3195E-06"
        ixz="1.0485E-07"
        iyy="0.00016848"
        iyz="-7.8362E-05"
        izz="0.00089359" />
    </inertial>
    <visual>
      <origin
        xyz="0 0 0"
        rpy="0 0 0" />
      <geometry>
        <mesh
          filename="package://STEP/meshes/link3.STL" />
      </geometry>
      <material
        name="">
        <color
          rgba="0.7451 0.7451 0.7451 1" />
      </material>
    </visual>
    <collision>
      <origin
        xyz="0 0 0"
        rpy="0 0 0" />
      <geometry>
        <mesh
          filename="package://STEP/meshes/link3.STL" />
      </geometry>
    </collision>
  </link>
  <joint
    name="3"
    type="revolute">
    <origin
      xyz="0.264 0.00763 0"
      rpy="-0.11394 0 1.5708" />
    <parent
      link="link2" />
    <child
      link="link3" />
    <axis
      xyz="1 0 0" />
    <limit
      lower="0"
      upper="3.1416"
      effort="0"
      velocity="0" />
  </joint>
  <link
    name="link4">
    <inertial>
      <origin
        xyz="-0.060694 0.050362 -0.036159"
        rpy="0 0 0" />
      <mass
        value="0.15929" />
      <inertia
        ixx="4.8974E-05"
        ixy="-2.9447E-10"
        ixz="-3.277E-08"
        iyy="6.1775E-05"
        iyz="6.849E-08"
        izz="4.529E-05" />
    </inertial>
    <visual>
      <origin
        xyz="0 0 0"
        rpy="0 0 0" />
      <geometry>
        <mesh
          filename="package://STEP/meshes/link4.STL" />
      </geometry>
      <material
        name="">
        <color
          rgba="0.75294 0.75294 0.75294 1" />
      </material>
    </visual>
    <collision>
      <origin
        xyz="0 0 0"
        rpy="0 0 0" />
      <geometry>
        <mesh
          filename="package://STEP/meshes/link4.STL" />
      </geometry>
    </collision>
  </link>
  <joint
    name="4"
    type="revolute">
    <origin
      xyz="-0.0015 0.2289 -0.034448"
      rpy="-1.5708 0.11394 -1.5708" />
    <parent
      link="link3" />
    <child
      link="link4" />
    <axis
      xyz="0 0 1" />
    <limit
      lower="-1.5708"
      upper="1.5708"
      effort="0"
      velocity="0" />
  </joint>
  <link
    name="link5">
    <inertial>
      <origin
        xyz="-1.2807E-05 -0.034473 0.01439"
        rpy="0 0 0" />
      <mass
        value="0.13379" />
      <inertia
        ixx="3.7178E-05"
        ixy="2.7193E-08"
        ixz="6.849E-08"
        iyy="3.75E-05"
        iyz="2.9447E-10"
        izz="5.1759E-05" />
    </inertial>
    <visual>
      <origin
        xyz="0 0 0"
        rpy="0 0 0" />
      <geometry>
        <mesh
          filename="package://STEP/meshes/link5.STL" />
      </geometry>
      <material
        name="">
        <color
          rgba="1 1 1 1" />
      </material>
    </visual>
    <collision>
      <origin
        xyz="0 0 0"
        rpy="0 0 0" />
      <geometry>
        <mesh
          filename="package://STEP/meshes/link5.STL" />
      </geometry>
    </collision>
  </link>
  <joint
    name="5"
    type="revolute">
    <origin
      xyz="-0.075 0.0385 -0.0345"
      rpy="3.1416 -1.5708 0" />
    <parent
      link="link4" />
    <child
      link="link5" />
    <axis
      xyz="0 1 0" />
    <limit
      lower="-1.5708"
      upper="1.5708"
      effort="0"
      velocity="0" />
  </joint>
  <link
    name="link6">
    <inertial>
      <origin
        xyz="-3.4881E-05 -0.014495 -0.043155"
        rpy="0 0 0" />
      <mass
        value="0.33362" />
      <inertia
        ixx="0.00020137"
        ixy="-9.5443E-08"
        ixz="-6.8488E-08"
        iyy="0.00016983"
        iyz="-3.2415E-06"
        izz="0.00025638" />
    </inertial>
    <visual>
      <origin
        xyz="0 0 0"
        rpy="0 0 0" />
      <geometry>
        <mesh
          filename="package://STEP/meshes/link6.STL" />
      </geometry>
      <material
        name="">
        <color
          rgba="0.75294 0.75294 0.75294 1" />
      </material>
    </visual>
    <collision>
      <origin
        xyz="0 0 0"
        rpy="0 0 0" />
      <geometry>
        <mesh
          filename="package://STEP/meshes/link6.STL" />
      </geometry>
    </collision>
  </link>
  <joint
    name="6"
    type="continuous">
    <origin
      xyz="0 -0.04 0.0565"
      rpy="3.1416 0 -3.1416" />
    <parent
      link="link5" />
    <child
      link="link6" />
    <axis
      xyz="0 0 1" />
    <limit
      lower="-1.5708"
      upper="1.5708"
      effort="0"
      velocity="0" />
  </joint>
</robot>