<sdf version='1.7'>
  <model name='STEP'>
    <link name='base_link'>
      <inertial>
        <pose>-2.3e-05 0 0.01623 0 -0 0</pose>
        <mass>0.50446</mass>
        <inertia>
          <ixx>0.00018822</ixx>
          <ixy>1.8597e-08</ixy>
          <ixz>-1.3884e-08</ixz>
          <iyy>0.0010487</iyy>
          <iyz>5.2358e-12</iyz>
          <izz>0.0011932</izz>
        </inertia>
      </inertial>
      <collision name='base_link_collision'>
        <pose>0 0 0 0 -0 0</pose>
        <geometry>
          <mesh>
            <scale>1 1 1</scale>
            <uri>/home/jinyuan/STEP/meshes/base_link.STL</uri>
          </mesh>
        </geometry>
      </collision>
      <visual name='base_link_visual'>
        <pose>0 0 0 0 -0 0</pose>
        <geometry>
          <mesh>
            <scale>1 1 1</scale>
            <uri>/home/jinyuan/STEP/meshes/base_link.STL</uri>
          </mesh>
        </geometry>
      </visual>
    </link>
    <joint name='1' type='revolute'>
      <pose relative_to='base_link'>0 0 0.12371 0 -0 0</pose>
      <parent>base_link</parent>
      <child>link1</child>
      <axis>
        <xyz>0 0 -1</xyz>
        <limit>
          <lower>0</lower>
          <upper>6.2832</upper>
          <effort>0</effort>
          <velocity>0</velocity>
        </limit>
        <dynamics>
          <spring_reference>0</spring_reference>
          <spring_stiffness>0</spring_stiffness>
        </dynamics>
      </axis>
    </joint>
    <link name='link1'>
      <pose relative_to='1'>0 0 0 0 -0 0</pose>
      <inertial>
        <pose>-0.004547 -0.002811 -0.030271 0 -0 0</pose>
        <mass>0.089464</mass>
        <inertia>
          <ixx>2.8404e-05</ixx>
          <ixy>1.2197e-08</ixy>
          <ixz>6.0756e-06</ixz>
          <iyy>2.686e-05</iyy>
          <iyz>-2.1814e-08</iyz>
          <izz>2.493e-05</izz>
        </inertia>
      </inertial>
      <collision name='link1_collision'>
        <pose>0 0 0 0 -0 0</pose>
        <geometry>
          <mesh>
            <scale>1 1 1</scale>
            <uri>/home/jinyuan/STEP/meshes/link1.STL</uri>
          </mesh>
        </geometry>
      </collision>
      <visual name='link1_visual'>
        <pose>0 0 0 0 -0 0</pose>
        <geometry>
          <mesh>
            <scale>1 1 1</scale>
            <uri>/home/jinyuan/STEP/meshes/link1.STL</uri>
          </mesh>
        </geometry>
      </visual>
    </link>
    <joint name='2' type='revolute'>
      <pose relative_to='link1'>-0.019 0 0 1.5708 -0 -3.14159</pose>
      <parent>link1</parent>
      <child>link2</child>
      <axis>
        <xyz>0 0 1</xyz>
        <limit>
          <lower>0</lower>
          <upper>3.662</upper>
          <effort>0</effort>
          <velocity>0</velocity>
        </limit>
        <dynamics>
          <spring_reference>0</spring_reference>
          <spring_stiffness>0</spring_stiffness>
        </dynamics>
      </axis>
    </joint>
    <link name='link2'>
      <pose relative_to='2'>0 0 0 0 -0 0</pose>
      <inertial>
        <pose>0.13073 0 0.002719 0 -0 0</pose>
        <mass>0.8789</mass>
        <inertia>
          <ixx>0.00021808</ixx>
          <ixy>3.8197e-08</ixy>
          <ixz>-6.9356e-19</ixz>
          <iyy>0.0010335</iyy>
          <iyz>-8.1073e-16</iyz>
          <izz>0.0011036</izz>
        </inertia>
      </inertial>
      <collision name='link2_collision'>
        <pose>0 0 0 0 -0 0</pose>
        <geometry>
          <mesh>
            <scale>1 1 1</scale>
            <uri>/home/jinyuan/STEP/meshes/link2.STL</uri>
          </mesh>
        </geometry>
      </collision>
      <visual name='link2_visual'>
        <pose>0 0 0 0 -0 0</pose>
        <geometry>
          <mesh>
            <scale>1 1 1</scale>
            <uri>/home/jinyuan/STEP/meshes/link2.STL</uri>
          </mesh>
        </geometry>
      </visual>
    </link>
    <joint name='3' type='revolute'>
      <pose relative_to='link2'>0.264 0 0 -3.14159 -0 2.8783</pose>
      <parent>link2</parent>
      <child>link3</child>
      <axis>
        <xyz>0 0 -1</xyz>
        <limit>
          <lower>-3.1416</lower>
          <upper>0</upper>
          <effort>0</effort>
          <velocity>0</velocity>
        </limit>
        <dynamics>
          <spring_reference>0</spring_reference>
          <spring_stiffness>0</spring_stiffness>
        </dynamics>
      </axis>
    </joint>
    <link name='link3'>
      <pose relative_to='3'>0 0 0 0 -0 0</pose>
      <inertial>
        <pose>0.1195 0.023882 -0.001697 0 -0 0</pose>
        <mass>0.71598</mass>
        <inertia>
          <ixx>0.00028128</ixx>
          <ixy>0.00016388</ixy>
          <ixz>-1.4389e-06</ixz>
          <iyy>0.00089643</iyy>
          <iyz>3.8117e-07</iyz>
          <izz>0.0010603</izz>
        </inertia>
      </inertial>
      <collision name='link3_collision'>
        <pose>0 0 0 0 -0 0</pose>
        <geometry>
          <mesh>
            <scale>1 1 1</scale>
            <uri>/home/jinyuan/STEP/meshes/link3.STL</uri>
          </mesh>
        </geometry>
      </collision>
      <visual name='link3_visual'>
        <pose>0 0 0 0 -0 0</pose>
        <geometry>
          <mesh>
            <scale>1 1 1</scale>
            <uri>/home/jinyuan/STEP/meshes/link3.STL</uri>
          </mesh>
        </geometry>
      </visual>
    </link>
    <joint name='4' type='revolute'>
      <pose relative_to='link3'>0.23148 0 0 0 0 -0.26332</pose>
      <parent>link3</parent>
      <child>link4</child>
      <axis>
        <xyz>0 0 -1</xyz>
        <limit>
          <lower>-1.5708</lower>
          <upper>1.5708</upper>
          <effort>0</effort>
          <velocity>0</velocity>
        </limit>
        <dynamics>
          <spring_reference>0</spring_reference>
          <spring_stiffness>0</spring_stiffness>
        </dynamics>
      </axis>
    </joint>
    <link name='link4'>
      <pose relative_to='4'>0 0 0 0 -0 0</pose>
      <inertial>
        <pose>0.052533 0.038815 0.000501 0 -0 0</pose>
        <mass>0.23515</mass>
        <inertia>
          <ixx>7.9691e-05</ixx>
          <ixy>2.9447e-10</ixy>
          <ixz>-4.225e-08</ixz>
          <iyy>9.4211e-05</iyy>
          <iyz>-6.849e-08</iyz>
          <izz>6.8988e-05</izz>
        </inertia>
      </inertial>
      <collision name='link4_collision'>
        <pose>0 0 0 0 -0 0</pose>
        <geometry>
          <mesh>
            <scale>1 1 1</scale>
            <uri>/home/jinyuan/STEP/meshes/link4.STL</uri>
          </mesh>
        </geometry>
      </collision>
      <visual name='link4_visual'>
        <pose>0 0 0 0 -0 0</pose>
        <geometry>
          <mesh>
            <scale>1 1 1</scale>
            <uri>/home/jinyuan/STEP/meshes/link4.STL</uri>
          </mesh>
        </geometry>
      </visual>
    </link>
    <joint name='5' type='revolute'>
      <pose relative_to='link4'>0.075 -0.0015 -0.0015 -1.57079 -1.57079 -3.14159</pose>
      <parent>link4</parent>
      <child>link5</child>
      <axis>
        <xyz>0 0 -1</xyz>
        <limit>
          <lower>-1.5708</lower>
          <upper>1.5708</upper>
          <effort>0</effort>
          <velocity>0</velocity>
        </limit>
        <dynamics>
          <spring_reference>0</spring_reference>
          <spring_stiffness>0</spring_stiffness>
        </dynamics>
      </axis>
    </joint>
    <link name='link5'>
      <pose relative_to='5'>0 0 0 0 -0 0</pose>
      <inertial>
        <pose>1e-05 -0.016598 -0.009317 0 -0 0</pose>
        <mass>0.16797</mass>
        <inertia>
          <ixx>4.8034e-05</ixx>
          <ixy>6.849e-08</ixy>
          <ixz>2.7193e-08</ixz>
          <iyy>6.7289e-05</iyy>
          <iyz>2.9447e-10</iyz>
          <izz>4.812e-05</izz>
        </inertia>
      </inertial>
      <collision name='link5_collision'>
        <pose>0 0 0 0 -0 0</pose>
        <geometry>
          <mesh>
            <scale>1 1 1</scale>
            <uri>/home/jinyuan/STEP/meshes/link5.STL</uri>
          </mesh>
        </geometry>
      </collision>
      <visual name='link5_visual'>
        <pose>0 0 0 0 -0 0</pose>
        <geometry>
          <mesh>
            <scale>1 1 1</scale>
            <uri>/home/jinyuan/STEP/meshes/link5.STL</uri>
          </mesh>
        </geometry>
      </visual>
    </link>
    <joint name='6' type='revolute'>
      <pose relative_to='link5'>0 -0.036 0 1.5708 -0 0</pose>
      <parent>link5</parent>
      <child>link6</child>
      <axis>
        <xyz>0 0 -1</xyz>
        <limit>
          <lower>-3.1416</lower>
          <upper>3.1416</upper>
          <effort>0</effort>
          <velocity>0</velocity>
        </limit>
        <dynamics>
          <spring_reference>0</spring_reference>
          <spring_stiffness>0</spring_stiffness>
        </dynamics>
      </axis>
    </joint>
    <link name='link6'>
      <pose relative_to='6'>0 0 0 0 -0 0</pose>
      <inertial>
        <pose>-3.5e-05 0.014495 0.063655 0 -0 0</pose>
        <mass>0.33362</mass>
        <inertia>
          <ixx>0.00020137</ixx>
          <ixy>9.5443e-08</ixy>
          <ixz>6.8488e-08</ixz>
          <iyy>0.00016983</iyy>
          <iyz>-3.2415e-06</iyz>
          <izz>0.00025638</izz>
        </inertia>
      </inertial>
      <collision name='link6_collision'>
        <pose>0 0 0 0 -0 0</pose>
        <geometry>
          <mesh>
            <scale>1 1 1</scale>
            <uri>/home/jinyuan/STEP/meshes/link6.STL</uri>
          </mesh>
        </geometry>
      </collision>
      <visual name='link6_visual'>
        <pose>0 0 0 0 -0 0</pose>
        <geometry>
          <mesh>
            <scale>1 1 1</scale>
            <uri>/home/jinyuan/STEP/meshes/link6.STL</uri>
          </mesh>
        </geometry>
      </visual>
    </link>
  </model>
</sdf>
